RELEASE_TYPE: patch

This patch fixes our workaround for `a pytest bug where the inner exceptions in
an ExceptionGroup are not displayed <https://github.com/pytest-dev/pytest/issues/9159>`__
(:issue:`3430`).
